Error Time: 2025-03-19 23:00:13
Error Message: eval_result should be a dictionary

Traceback (most recent call last):
  File "/home/ym/code/ML_training/week3/unknown48/train_gbdt.py", line 332, in <module>
    mse, r2, pearson = main()
  File "/home/ym/code/ML_training/week3/unknown48/train_gbdt.py", line 301, in main
    model = train_model(x_train_split, y_train_split, x_val, y_val, vis_dir)
  File "/home/ym/code/ML_training/week3/unknown48/train_gbdt.py", line 168, in train_model
    lgb.record_evaluation(vis_dir)
  File "/root/anaconda3/envs/mlenv/lib/python3.10/site-packages/lightgbm/callback.py", line 216, in record_evaluation
    return _RecordEvaluationCallback(eval_result=eval_result)
  File "/root/anaconda3/envs/mlenv/lib/python3.10/site-packages/lightgbm/callback.py", line 143, in __init__
    raise TypeError("eval_result should be a dictionary")
TypeError: eval_result should be a dictionary
